ERROR:uvicorn.error:Exception in ASGI application
Traceback (most recent call last):
  File "d:\program\anaconda3\lib\site-packages\uvicorn\protocols\http\httptools_impl.py", line 375, in run_asgi
    result = await app(self.scope, self.receive, self.send)
  File "d:\program\anaconda3\lib\site-packages\uvicorn\middleware\proxy_headers.py", line 75, in __call__
    return await self.app(scope, receive, send)
  File "d:\program\anaconda3\lib\site-packages\fastapi\applications.py", line 208, in __call__
    await super().__call__(scope, receive, send)
  File "d:\program\anaconda3\lib\site-packages\starlette\applications.py", line 112, in __call__
    await self.middleware_stack(scope, receive, send)
  File "d:\program\anaconda3\lib\site-packages\starlette\middleware\errors.py", line 181, in __call__
    raise exc from None
  File "d:\program\anaconda3\lib\site-packages\starlette\middleware\errors.py", line 159, in __call__
    await self.app(scope, receive, _send)
  File "d:\program\anaconda3\lib\site-packages\starlette\middleware\cors.py", line 86, in __call__
    await self.simple_response(scope, receive, send, request_headers=headers)
  File "d:\program\anaconda3\lib\site-packages\starlette\middleware\cors.py", line 142, in simple_response
    await self.app(scope, receive, send)
  File "d:\program\anaconda3\lib\site-packages\starlette\exceptions.py", line 82, in __call__
    raise exc from None
  File "d:\program\anaconda3\lib\site-packages\starlette\exceptions.py", line 71, in __call__
    await self.app(scope, receive, sender)
  File "d:\program\anaconda3\lib\site-packages\starlette\routing.py", line 580, in __call__
    await route.handle(scope, receive, send)
  File "d:\program\anaconda3\lib\site-packages\starlette\routing.py", line 241, in handle
    await self.app(scope, receive, send)
  File "d:\program\anaconda3\lib\site-packages\starlette\routing.py", line 52, in app
    response = await func(request)
  File "d:\program\anaconda3\lib\site-packages\fastapi\routing.py", line 227, in app
    dependant=dependant, values=values, is_coroutine=is_coroutine
  File "d:\program\anaconda3\lib\site-packages\fastapi\routing.py", line 159, in run_endpoint_function
    return await dependant.call(**values)
  File ".\index\index\login.py", line 33, in save
    token=setToken(u["userid"],p["password"])
  File ".\ext\userAccess.py", line 11, in setToken
    cache.cacheSet(token,userid,token_expire)
  File ".\ext\cache.py", line 5, in cacheSet
    MM("index","dbcache").where("k=%s").update("v=%s,expire=%s",[str(v),expire,k])
  File ".\model.py", line 134, in update
    logging.basicConfig(filename='example.log', encoding='utf-8', level=logging.DEBUG)
  File "d:\program\anaconda3\lib\logging\__init__.py", line 1916, in basicConfig
    raise ValueError('Unrecognised argument(s): %s' % keys)
ValueError: Unrecognised argument(s): encoding
